Traceback (most recent call last):
  File "./api.py", line 86, in <module>
    app.run(host='0.0.0.0')
  File "/usr/local/lib/python2.7/dist-packages/flask/app.py", line 772, in run
    run_simple(host, port, self, **options)
  File "/usr/local/lib/python2.7/dist-packages/werkzeug/serving.py", line 694, in run_simple
    inner()
  File "/usr/local/lib/python2.7/dist-packages/werkzeug/serving.py", line 656, in inner
    fd=fd)
  File "/usr/local/lib/python2.7/dist-packages/werkzeug/serving.py", line 550, in make_server
    passthrough_errors, ssl_context, fd=fd)
  File "/usr/local/lib/python2.7/dist-packages/werkzeug/serving.py", line 464, in __init__
    HTTPServer.__init__(self, (host, int(port)), handler)
  File "/usr/lib/python2.7/SocketServer.py", line 420, in __init__
    self.server_bind()
  File "/usr/lib/python2.7/BaseHTTPServer.py", line 108, in server_bind
    SocketServer.TCPServer.server_bind(self)
  File "/usr/lib/python2.7/SocketServer.py", line 434, in server_bind
    self.socket.bind(self.server_address)
  File "/usr/lib/python2.7/socket.py", line 224, in meth
    return getattr(self._sock,name)(*args)
socket.error: [Errno 98] Address already in use
Traceback (most recent call last):
  File "./api.py", line 2, in <module>
    from flask import Flask, jsonify, abort, make_response, request, url_for, CORS
ImportError: cannot import name CORS
Traceback (most recent call last):
  File "./api.py", line 2, in <module>
    from flask import Flask, jsonify, abort, make_response, request, url_for, CORS
ImportError: cannot import name CORS
Traceback (most recent call last):
  File "./api.py", line 69, in <module>
    app.run(host='0.0.0.0')
  File "/usr/local/lib/python2.7/dist-packages/flask/app.py", line 772, in run
    run_simple(host, port, self, **options)
  File "/usr/local/lib/python2.7/dist-packages/werkzeug/serving.py", line 694, in run_simple
    inner()
  File "/usr/local/lib/python2.7/dist-packages/werkzeug/serving.py", line 656, in inner
    fd=fd)
  File "/usr/local/lib/python2.7/dist-packages/werkzeug/serving.py", line 550, in make_server
    passthrough_errors, ssl_context, fd=fd)
  File "/usr/local/lib/python2.7/dist-packages/werkzeug/serving.py", line 464, in __init__
    HTTPServer.__init__(self, (host, int(port)), handler)
  File "/usr/lib/python2.7/SocketServer.py", line 420, in __init__
    self.server_bind()
  File "/usr/lib/python2.7/BaseHTTPServer.py", line 108, in server_bind
    SocketServer.TCPServer.server_bind(self)
  File "/usr/lib/python2.7/SocketServer.py", line 434, in server_bind
    self.socket.bind(self.server_address)
  File "/usr/lib/python2.7/socket.py", line 224, in meth
    return getattr(self._sock,name)(*args)
socket.error: [Errno 98] Address already in use
Traceback (most recent call last):
  File "./api.py", line 69, in <module>
    app.run(host='0.0.0.0')
  File "/usr/local/lib/python2.7/dist-packages/flask/app.py", line 772, in run
    run_simple(host, port, self, **options)
  File "/usr/local/lib/python2.7/dist-packages/werkzeug/serving.py", line 694, in run_simple
    inner()
  File "/usr/local/lib/python2.7/dist-packages/werkzeug/serving.py", line 656, in inner
    fd=fd)
  File "/usr/local/lib/python2.7/dist-packages/werkzeug/serving.py", line 550, in make_server
    passthrough_errors, ssl_context, fd=fd)
  File "/usr/local/lib/python2.7/dist-packages/werkzeug/serving.py", line 464, in __init__
    HTTPServer.__init__(self, (host, int(port)), handler)
  File "/usr/lib/python2.7/SocketServer.py", line 420, in __init__
    self.server_bind()
  File "/usr/lib/python2.7/BaseHTTPServer.py", line 108, in server_bind
    SocketServer.TCPServer.server_bind(self)
  File "/usr/lib/python2.7/SocketServer.py", line 434, in server_bind
    self.socket.bind(self.server_address)
  File "/usr/lib/python2.7/socket.py", line 224, in meth
    return getattr(self._sock,name)(*args)
socket.error: [Errno 98] Address already in use
